Workbook

Sheet Sheet1
A1: Invoice ID | B1: Branch | C1: City | D1: Customer type | E1: Gender | F1: Product line | G1: Unit price | H1: Quantity | I1: Tax 5% | J1: Total | K1: Date | L1: Time | M1: Payment | N1: cogs | O1: Rating
A2: 750-67-8428 | B2: A | C2: Yangon | D2: Member | E2: Female | F2: Health and beauty | G2: 74.69 | H2: 7 | I2: 26.1415 | J2: 548.9715 | K2: 43470 | L2: 0.54722222 | M2: Ewallet | N2: 522.83 | O2: 9.1
A3: 226-31-3081 | B3: C | C3: Naypyitaw | D3: Normal | E3: Female | F3: Electronic accessories | G3: 15.28 | H3: 5 | I3: 3.82 | J3: 80.22 | K3: 43532 | L3: 0.43680556 | M3: Cash | N3: 76.4 | O3: 9.6
A4: 631-41-3108 | B4: A | C4: Yangon | D4: Normal | E4: Male | F4: Home and lifestyle | G4: 46.33 | H4: 7 | I4: 16.2155 | J4: 340.5255 | K4: 43527 | L4: 0.55763889 | M4: Credit card | N4: 324.31 | O4: 7.4
A5: 123-19-1176 | B5: A | C5: Yangon | D5: Member | E5: Male | F5: Health and beauty | G5: 58.22 | H5: 8 | I5: 23.288 | J5: 489.048 | K5: 43492 | L5: 0.85625 | M5: Ewallet | N5: 465.76 | O5: 8.4
A6: 373-73-7910 | B6: A | C6: Yangon | D6: Normal | E6: Male | F6: Sports and travel | G6: 86.31 | H6: 7 | I6: 30.2085 | J6: 634.3785 | K6: 43504 | L6: 0.44236111 | M6: Ewallet | N6: 604.17 | O6: 5.3
A7: 699-14-3026 | B7: C | C7: Naypyitaw | D7: Normal | E7: Male | F7: Electronic accessories | G7: 85.39 | H7: 7 | I7: 29.8865 | J7: 627.6165 | K7: 43549 | L7: 0.77083333 | M7: Ewallet | N7: 597.73 | O7: 4.1
A8: 355-53-5943 | B8: A | C8: Yangon | D8: Member | E8: Female | F8: Electronic accessories | G8: 68.84 | H8: 6 | I8: 20.652 | J8: 433.692 | K8: 43521 | L8: 0.60833333 | M8: Ewallet | N8: 413.04 | O8: 5.8
A9: 315-22-5665 | B9: C | C9: Naypyitaw | D9: Normal | E9: Female | F9: Home and lifestyle | G9: 73.56 | H9: 10 | I9: 36.78 | J9: 772.38 | K9: 43520 | L9: 0.48472222 | M9: Ewallet | N9: 735.6 | O9: 8
A10: 665-32-9167 | B10: A | C10: Yangon | D10: Member | E10: Female | F10: Health and beauty | G10: 36.26 | H10: 2 | I10: 3.626 | J10: 76.146 | K10: 43475 | L10: 0.71875 | M10: Credit card | N10: 72.52 | O10: 7.2
A11: 692-92-5582 | B11: B | C11: Mandalay | D11: Member | E11: Female | F11: Food and beverages | G11: 54.84 | H11: 3 | I11: 8.226 | J11: 172.746 | K11: 43516 | L11: 0.56041667 | M11: Credit card | N11: 164.52 | O11: 5.9
A12: 351-62-0822 | B12: B | C12: Mandalay | D12: Member | E12: Female | F12: Fashion accessories | G12: 14.48 | H12: 4 | I12: 2.896 | J12: 60.816 | K12: 43502 | L12: 0.75486111 | M12: Ewallet | N12: 57.92 | O12: 4.5
A13: 529-56-3974 | B13: B | C13: Mandalay | D13: Member | E13: Male | F13: Electronic accessories | G13: 25.51 | H13: 4 | I13: 5.102 | J13: 107.142 | K13: 43533 | L13: 0.71041667 | M13: Cash | N13: 102.04 | O13: 6.8
... A1001: 849-09-3807 | B1001: A | C1001: Yangon | D1001: Member | E1001: Female | F1001: Fashion accessories | G1001: 88.34 | H1001: 7 | I1001: 30.919 | J1001: 649.299 | K1001: 43514 | L1001: 0.56111111 | M1001: Cash | N1001: 618.38 | O1001: 6.6

Sheet Tasks
A1: Task | B1: Question | C1: Answer here if it single value | E1: First 3 Invoice ID | F1: Last 4 Invoice ID | G1: Middle 2 Invoice ID | H1: Concatenate | I1: Combining "Yangon_1/5/2019" | J1: Tax 5% = 5% of cogs | K1: Check if cogs equals Unit price multiplied by Quantity | L1: is City contains text values | M1: is Total contains text values | N1: "A" or "B" Branch | O1: Check if "Credit card" | P1: Rating is greater than 7
A2: 1 | B2: What is the total revenue (Total column) generated by all transactions? | C2: =SUM(Sheet1!J2:J1001) -> 322966.75 | E2: {=LEFT(Sheet1!A2:A1001,3)} -> 750 | F2: {=RIGHT(Sheet1!A2:A1001,4)} -> 8428 | G2: {=MID(Sheet1!A2:A1001,5,2)} -> 67 | H2: =_xlfn.CONCAT(Sheet1!A2," --> ",Sheet1!J2) -> 750-67-8428 --> 548.9715 | I2: =_xlfn.CONCAT(Sheet1!C2,"_",TEXT(Sheet1!K2, "m/d/yyyy")) -> Yangon_1/5/2019 | J2: =IF(Sheet1!I2=Sheet1!N2*0.05,"Valid","Error") -> Valid | K2: =IF(Sheet1!N2=Sheet1!G2*Sheet1!H2,"True","False") -> True | L2: {=ISTEXT(Sheet1!C2:C1001)} -> TRUE | M2: =ISNUMBER(Sheet1!J2) -> TRUE | N2: =IF(Sheet1!B2="A","Branch A",IF(Sheet1!B2="B","Branch B","Other Branch")) -> Branch A | O2: =IF(Sheet1!M2="Credit card","Credit Payment","Other") -> Other | P2: =IF(Sheet1!O2>7,"Yes","No") -> Yes
A3: 2 | B3: What is the total Quantity sold across all transactions? | C3: =SUM(Sheet1!H2:H1001) -> 5510 | E3: 226 | F3: 3081 | G3: 31 | H3: =_xlfn.CONCAT(Sheet1!A3," --> ",Sheet1!J3) -> 226-31-3081 --> 80.22 | I3: =_xlfn.CONCAT(Sheet1!C3,"_",TEXT(Sheet1!K3, "m/d/yyyy")) -> Naypyitaw_3/8/2019 | J3: =IF(Sheet1!I3=Sheet1!N3*0.05,"Valid","Error") -> Valid | K3: =IF(Sheet1!N3=Sheet1!G3*Sheet1!H3,"True","False") -> True | L3: TRUE | M3: =ISNUMBER(Sheet1!J3) -> TRUE | N3: =IF(Sheet1!B3="A","Branch A",IF(Sheet1!B3="B","Branch B","Other Branch")) -> Other Branch | O3: =IF(Sheet1!M3="Credit card","Credit Payment","Other") -> Other | P3: =IF(Sheet1!O3>7,"Yes","No") -> Yes
A4: 3 | B4: What is the minimum Unit price in the dataset? | C4: =MIN(Sheet1!G2:G1001) -> 10.08 | E4: 631 | F4: 3108 | G4: 41 | H4: =_xlfn.CONCAT(Sheet1!A4," --> ",Sheet1!J4) -> 631-41-3108 --> 340.5255 | I4: =_xlfn.CONCAT(Sheet1!C4,"_",TEXT(Sheet1!K4, "m/d/yyyy")) -> Yangon_3/3/2019 | J4: =IF(Sheet1!I4=Sheet1!N4*0.05,"Valid","Error") -> Valid | K4: =IF(Sheet1!N4=Sheet1!G4*Sheet1!H4,"True","False") -> True | L4: TRUE | M4: =ISNUMBER(Sheet1!J4) -> TRUE | N4: =IF(Sheet1!B4="A","Branch A",IF(Sheet1!B4="B","Branch B","Other Branch")) -> Branch A | O4: =IF(Sheet1!M4="Credit card","Credit Payment","Other") -> Credit Payment | P4: =IF(Sheet1!O4>7,"Yes","No") -> Yes
A5: 4 | B5: What is the maximum Rating in the dataset? | C5: =MAX(Sheet1!O2:O1001) -> 10 | E5: 123 | F5: 1176 | G5: 19 | H5: =_xlfn.CONCAT(Sheet1!A5," --> ",Sheet1!J5) -> 123-19-1176 --> 489.048 | I5: =_xlfn.CONCAT(Sheet1!C5,"_",TEXT(Sheet1!K5, "m/d/yyyy")) -> Yangon_1/27/2019 | J5: =IF(Sheet1!I5=Sheet1!N5*0.05,"Valid","Error") -> Valid | K5: =IF(Sheet1!N5=Sheet1!G5*Sheet1!H5,"True","False") -> True | L5: TRUE | M5: =ISNUMBER(Sheet1!J5) -> TRUE | N5: =IF(Sheet1!B5="A","Branch A",IF(Sheet1!B5="B","Branch B","Other Branch")) -> Branch A | O5: =IF(Sheet1!M5="Credit card","Credit Payment","Other") -> Other | P5: =IF(Sheet1!O5>7,"Yes","No") -> Yes
A6: 5 | B6: What is the average Total value of all transactions? | C6: =AVERAGE(Sheet1!J2:J1001) -> 322.96675 | E6: 373 | F6: 7910 | G6: 73 | H6: =_xlfn.CONCAT(Sheet1!A6," --> ",Sheet1!J6) -> 373-73-7910 --> 634.3785 | I6: =_xlfn.CONCAT(Sheet1!C6,"_",TEXT(Sheet1!K6, "m/d/yyyy")) -> Yangon_2/8/2019 | J6: =IF(Sheet1!I6=Sheet1!N6*0.05,"Valid","Error") -> Valid | K6: =IF(Sheet1!N6=Sheet1!G6*Sheet1!H6,"True","False") -> True | L6: TRUE | M6: =ISNUMBER(Sheet1!J6) -> TRUE | N6: =IF(Sheet1!B6="A","Branch A",IF(Sheet1!B6="B","Branch B","Other Branch")) -> Branch A | O6: =IF(Sheet1!M6="Credit card","Credit Payment","Other") -> Other | P6: =IF(Sheet1!O6>7,"Yes","No") -> No
A7: 6 | B7: What is the average cogs across all transactions? | C7: =AVERAGE(Sheet1!N2:N1001) -> 307.58738 | E7: 699 | F7: 3026 | G7: 14 | H7: =_xlfn.CONCAT(Sheet1!A7," --> ",Sheet1!J7) -> 699-14-3026 --> 627.6165 | I7: =_xlfn.CONCAT(Sheet1!C7,"_",TEXT(Sheet1!K7, "m/d/yyyy")) -> Naypyitaw_3/25/2019 | J7: =IF(Sheet1!I7=Sheet1!N7*0.05,"Valid","Error") -> Valid | K7: =IF(Sheet1!N7=Sheet1!G7*Sheet1!H7,"True","False") -> True | L7: TRUE | M7: =ISNUMBER(Sheet1!J7) -> TRUE | N7: =IF(Sheet1!B7="A","Branch A",IF(Sheet1!B7="B","Branch B","Other Branch")) -> Other Branch | O7: =IF(Sheet1!M7="Credit card","Credit Payment","Other") -> Other | P7: =IF(Sheet1!O7>7,"Yes","No") -> No
A8: 7 | B8: What is the total revenue (Total) for the City of Yangon? | C8: =SUMIF(Sheet1!C2:C1001,"Yangon",Sheet1!J2:J1001) -> 106200.37 | E8: 355 | F8: 5943 | G8: 53 | H8: =_xlfn.CONCAT(Sheet1!A8," --> ",Sheet1!J8) -> 355-53-5943 --> 433.692 | I8: =_xlfn.CONCAT(Sheet1!C8,"_",TEXT(Sheet1!K8, "m/d/yyyy")) -> Yangon_2/25/2019 | J8: =IF(Sheet1!I8=Sheet1!N8*0.05,"Valid","Error") -> Valid | K8: =IF(Sheet1!N8=Sheet1!G8*Sheet1!H8,"True","False") -> True | L8: TRUE | M8: =ISNUMBER(Sheet1!J8) -> TRUE | N8: =IF(Sheet1!B8="A","Branch A",IF(Sheet1!B8="B","Branch B","Other Branch")) -> Branch A | O8: =IF(Sheet1!M8="Credit card","Credit Payment","Other") -> Other | P8: =IF(Sheet1!O8>7,"Yes","No") -> No
A9: 8 | B9: What is the total Quantity sold for Product line "Health and beauty"? | C9: =SUMIF(Sheet1!F2:F1001,"Health and beauty",Sheet1!H2:H1001) -> 854 | E9: 315 | F9: 5665 | G9: 22 | H9: =_xlfn.CONCAT(Sheet1!A9," --> ",Sheet1!J9) -> 315-22-5665 --> 772.38 | I9: =_xlfn.CONCAT(Sheet1!C9,"_",TEXT(Sheet1!K9, "m/d/yyyy")) -> Naypyitaw_2/24/2019 | J9: =IF(Sheet1!I9=Sheet1!N9*0.05,"Valid","Error") -> Valid | K9: =IF(Sheet1!N9=Sheet1!G9*Sheet1!H9,"True","False") -> True | L9: TRUE | M9: =ISNUMBER(Sheet1!J9) -> TRUE | N9: =IF(Sheet1!B9="A","Branch A",IF(Sheet1!B9="B","Branch B","Other Branch")) -> Other Branch | O9: =IF(Sheet1!M9="Credit card","Credit Payment","Other") -> Other | P9: =IF(Sheet1!O9>7,"Yes","No") -> Yes
A10: 9 | B10: How many transactions were made using the Payment method "Cash"? | C10: =COUNTIF(Sheet1!M2:M1001, "Cash") -> 344 | E10: 665 | F10: 9167 | G10: 32 | H10: =_xlfn.CONCAT(Sheet1!A10," --> ",Sheet1!J10) -> 665-32-9167 --> 76.146 | I10: =_xlfn.CONCAT(Sheet1!C10,"_",TEXT(Sheet1!K10, "m/d/yyyy")) -> Yangon_1/10/2019 | J10: =IF(Sheet1!I10=Sheet1!N10*0.05,"Valid","Error") -> Valid | K10: =IF(Sheet1!N10=Sheet1!G10*Sheet1!H10,"True","False") -> True | L10: TRUE | M10: =ISNUMBER(Sheet1!J10) -> TRUE | N10: =IF(Sheet1!B10="A","Branch A",IF(Sheet1!B10="B","Branch B","Other Branch")) -> Branch A | O10: =IF(Sheet1!M10="Credit card","Credit Payment","Other") -> Credit Payment | P10: =IF(Sheet1!O10>7,"Yes","No") -> Yes
A11: 10 | B11: Count the number of customers with a Rating greater than 8. | C11: =COUNTIF(Sheet1!O2:O1001,">8") -> 308 | E11: 692 | F11: 5582 | G11: 92 | H11: =_xlfn.CONCAT(Sheet1!A11," --> ",Sheet1!J11) -> 692-92-5582 --> 172.746 | I11: =_xlfn.CONCAT(Sheet1!C11,"_",TEXT(Sheet1!K11, "m/d/yyyy")) -> Mandalay_2/20/2019 | J11: =IF(Sheet1!I11=Sheet1!N11*0.05,"Valid","Error") -> Valid | K11: =IF(Sheet1!N11=Sheet1!G11*Sheet1!H11,"True","False") -> True | L11: TRUE | M11: =ISNUMBER(Sheet1!J11) -> TRUE | N11: =IF(Sheet1!B11="A","Branch A",IF(Sheet1!B11="B","Branch B","Other Branch")) -> Branch B | O11: =IF(Sheet1!M11="Credit card","Credit Payment","Other") -> Credit Payment | P11: =IF(Sheet1!O11>7,"Yes","No") -> No
A12: 11 | B12: What is the average Unit price for Product line "Electronic accessories"? | C12: =AVERAGEIF(Sheet1!F2:F1001,"Electronic accessories",Sheet1!G2:G1001) -> 53.551588 | E12: 351 | F12: 0822 | G12: 62 | H12: =_xlfn.CONCAT(Sheet1!A12," --> ",Sheet1!J12) -> 351-62-0822 --> 60.816 | I12: =_xlfn.CONCAT(Sheet1!C12,"_",TEXT(Sheet1!K12, "m/d/yyyy")) -> Mandalay_2/6/2019 | J12: =IF(Sheet1!I12=Sheet1!N12*0.05,"Valid","Error") -> Valid | K12: =IF(Sheet1!N12=Sheet1!G12*Sheet1!H12,"True","False") -> True | L12: TRUE | M12: =ISNUMBER(Sheet1!J12) -> TRUE | N12: =IF(Sheet1!B12="A","Branch A",IF(Sheet1!B12="B","Branch B","Other Branch")) -> Branch B | O12: =IF(Sheet1!M12="Credit card","Credit Payment","Other") -> Other | P12: =IF(Sheet1!O12>7,"Yes","No") -> No
A13: 12 | B13: Find the average cogs for all transactions with City "Mandalay". | C13: =AVERAGEIF(Sheet1!C2:C1001,"Mandalay",Sheet1!N2:N1001) -> 304.64048 | E13: 529 | F13: 3974 | G13: 56 | H13: =_xlfn.CONCAT(Sheet1!A13," --> ",Sheet1!J13) -> 529-56-3974 --> 107.142 | I13: =_xlfn.CONCAT(Sheet1!C13,"_",TEXT(Sheet1!K13, "m/d/yyyy")) -> Mandalay_3/9/2019 | J13: =IF(Sheet1!I13=Sheet1!N13*0.05,"Valid","Error") -> Valid | K13: =IF(Sheet1!N13=Sheet1!G13*Sheet1!H13,"True","False") -> True | L13: TRUE | M13: =ISNUMBER(Sheet1!J13) -> TRUE | N13: =IF(Sheet1!B13="A","Branch A",IF(Sheet1!B13="B","Branch B","Other Branch")) -> Branch B | O13: =IF(Sheet1!M13="Credit card","Credit Payment","Other") -> Other | P13: =IF(Sheet1!O13>7,"Yes","No") -> No
A14: 13 | B14: Find the 3rd highest Total value. | C14: =LARGE(_xlfn.UNIQUE(Sheet1!J2:J1001),3) -> 1034.46 | E14: 365 | F14: 0515 | G14: 64 | H14: =_xlfn.CONCAT(Sheet1!A14," --> ",Sheet1!J14) -> 365-64-0515 --> 246.4875 | I14: =_xlfn.CONCAT(Sheet1!C14,"_",TEXT(Sheet1!K14, "m/d/yyyy")) -> Yangon_2/12/2019 | J14: =IF(Sheet1!I14=Sheet1!N14*0.05,"Valid","Error") -> Valid | K14: =IF(Sheet1!N14=Sheet1!G14*Sheet1!H14,"True","False") -> True | L14: TRUE | M14: =ISNUMBER(Sheet1!J14) -> TRUE | N14: =IF(Sheet1!B14="A","Branch A",IF(Sheet1!B14="B","Branch B","Other Branch")) -> Branch A | O14: =IF(Sheet1!M14="Credit card","Credit Payment","Other") -> Other | P14: =IF(Sheet1!O14>7,"Yes","No") -> Yes
A15: 14 | B15: Identify the 2nd smallest Quantity. | C15: =SMALL(_xlfn.UNIQUE(Sheet1!H2:H1001),2) -> 2 | E15: 252 | F15: 2699 | G15: 56 | H15: =_xlfn.CONCAT(Sheet1!A15," --> ",Sheet1!J15) -> 252-56-2699 --> 453.495 | I15: =_xlfn.CONCAT(Sheet1!C15,"_",TEXT(Sheet1!K15, "m/d/yyyy")) -> Yangon_2/7/2019 | J15: =IF(Sheet1!I15=Sheet1!N15*0.05,"Valid","Error") -> Valid | K15: =IF(Sheet1!N15=Sheet1!G15*Sheet1!H15,"True","False") -> True | L15: TRUE | M15: =ISNUMBER(Sheet1!J15) -> TRUE | N15: =IF(Sheet1!B15="A","Branch A",IF(Sheet1!B15="B","Branch B","Other Branch")) -> Branch A | O15: =IF(Sheet1!M15="Credit card","Credit Payment","Other") -> Other | P15: =IF(Sheet1!O15>7,"Yes","No") -> Yes
A16: 15 | B16: Extract the first 3 characters of the Invoice ID. | E16: 829 | F16: 3910 | G16: 34 | H16: =_xlfn.CONCAT(Sheet1!A16," --> ",Sheet1!J16) -> 829-34-3910 --> 749.49 | I16: =_xlfn.CONCAT(Sheet1!C16,"_",TEXT(Sheet1!K16, "m/d/yyyy")) -> Yangon_3/29/2019 | J16: =IF(Sheet1!I16=Sheet1!N16*0.05,"Valid","Error") -> Valid | K16: =IF(Sheet1!N16=Sheet1!G16*Sheet1!H16,"True","False") -> True | L16: TRUE | M16: =ISNUMBER(Sheet1!J16) -> TRUE | N16: =IF(Sheet1!B16="A","Branch A",IF(Sheet1!B16="B","Branch B","Other Branch")) -> Branch A | O16: =IF(Sheet1!M16="Credit card","Credit Payment","Other") -> Other | P16: =IF(Sheet1!O16>7,"Yes","No") -> No
A17: 16 | B17: Extract the last 4 digits of the Invoice ID. | E17: 299 | F17: 1805 | G17: 46 | H17: =_xlfn.CONCAT(Sheet1!A17," --> ",Sheet1!J17) -> 299-46-1805 --> 590.436 | I17: =_xlfn.CONCAT(Sheet1!C17,"_",TEXT(Sheet1!K17, "m/d/yyyy")) -> Mandalay_1/15/2019 | J17: =IF(Sheet1!I17=Sheet1!N17*0.05,"Valid","Error") -> Valid | K17: =IF(Sheet1!N17=Sheet1!G17*Sheet1!H17,"True","False") -> True | L17: TRUE | M17: =ISNUMBER(Sheet1!J17) -> TRUE | N17: =IF(Sheet1!B17="A","Branch A",IF(Sheet1!B17="B","Branch B","Other Branch")) -> Branch B | O17: =IF(Sheet1!M17="Credit card","Credit Payment","Other") -> Other | P17: =IF(Sheet1!O17>7,"Yes","No") -> No
A18: 17 | B18: Extract the middle 2 digits from the 5th position of the Invoice ID. | E18: 656 | F18: 9349 | G18: 95 | H18: =_xlfn.CONCAT(Sheet1!A18," --> ",Sheet1!J18) -> 656-95-9349 --> 506.6355 | I18: =_xlfn.CONCAT(Sheet1!C18,"_",TEXT(Sheet1!K18, "m/d/yyyy")) -> Yangon_3/11/2019 | J18: =IF(Sheet1!I18=Sheet1!N18*0.05,"Valid","Error") -> Valid | K18: =IF(Sheet1!N18=Sheet1!G18*Sheet1!H18,"True","False") -> True | L18: TRUE | M18: =ISNUMBER(Sheet1!J18) -> TRUE | N18: =IF(Sheet1!B18="A","Branch A",IF(Sheet1!B18="B","Branch B","Other Branch")) -> Branch A | O18: =IF(Sheet1!M18="Credit card","Credit Payment","Other") -> Credit Payment | P18: =IF(Sheet1!O18>7,"Yes","No") -> No
A19: 18 | B19: Ensure there are no extra spaces in the Payment column. | C19: =COUNTBLANK(Sheet1!M2:M1001) -> 0 | E19: 765 | F19: 6951 | G19: 26 | H19: =_xlfn.CONCAT(Sheet1!A19," --> ",Sheet1!J19) -> 765-26-6951 --> 457.443 | I19: =_xlfn.CONCAT(Sheet1!C19,"_",TEXT(Sheet1!K19, "m/d/yyyy")) -> Yangon_1/1/2019 | J19: =IF(Sheet1!I19=Sheet1!N19*0.05,"Valid","Error") -> Valid | K19: =IF(Sheet1!N19=Sheet1!G19*Sheet1!H19,"True","False") -> True | L19: TRUE | M19: =ISNUMBER(Sheet1!J19) -> TRUE | N19: =IF(Sheet1!B19="A","Branch A",IF(Sheet1!B19="B","Branch B","Other Branch")) -> Branch A | O19: =IF(Sheet1!M19="Credit card","Credit Payment","Other") -> Credit Payment | P19: =IF(Sheet1!O19>7,"Yes","No") -> No
A20: 19 | B20: Concatenate the Invoice ID with the Total. | E20: 329 | F20: 1586 | G20: 62 | H20: =_xlfn.CONCAT(Sheet1!A20," --> ",Sheet1!J20) -> 329-62-1586 --> 172.2105 | I20: =_xlfn.CONCAT(Sheet1!C20,"_",TEXT(Sheet1!K20, "m/d/yyyy")) -> Yangon_1/21/2019 | J20: =IF(Sheet1!I20=Sheet1!N20*0.05,"Valid","Error") -> Valid | K20: =IF(Sheet1!N20=Sheet1!G20*Sheet1!H20,"True","False") -> True | L20: TRUE | M20: =ISNUMBER(Sheet1!J20) -> TRUE | N20: =IF(Sheet1!B20="A","Branch A",IF(Sheet1!B20="B","Branch B","Other Branch")) -> Branch A | O20: =IF(Sheet1!M20="Credit card","Credit Payment","Other") -> Credit Payment | P20: =IF(Sheet1!O20>7,"Yes","No") -> Yes
A21: 20 | B21: Create a string combining City and Date in the format "Yangon_1/5/2019". | E21: 319 | F21: 3348 | G21: 50 | H21: =_xlfn.CONCAT(Sheet1!A21," --> ",Sheet1!J21) -> 319-50-3348 --> 84.63 | I21: =_xlfn.CONCAT(Sheet1!C21,"_",TEXT(Sheet1!K21, "m/d/yyyy")) -> Mandalay_3/11/2019 | J21: =IF(Sheet1!I21=Sheet1!N21*0.05,"Valid","Error") -> Valid | K21: =IF(Sheet1!N21=Sheet1!G21*Sheet1!H21,"True","False") -> True | L21: TRUE | M21: =ISNUMBER(Sheet1!J21) -> TRUE | N21: =IF(Sheet1!B21="A","Branch A",IF(Sheet1!B21="B","Branch B","Other Branch")) -> Branch B | O21: =IF(Sheet1!M21="Credit card","Credit Payment","Other") -> Other | P21: =IF(Sheet1!O21>7,"Yes","No") -> No
A22: 21 | B22: Count the number of transactions with Rating greater than 9. | C22: =COUNTIF(Sheet1!O2:O1001,">9") -> 151 | E22: 300 | F22: 4605 | G22: 71 | H22: =_xlfn.CONCAT(Sheet1!A22," --> ",Sheet1!J22) -> 300-71-4605 --> 451.71 | I22: =_xlfn.CONCAT(Sheet1!C22,"_",TEXT(Sheet1!K22, "m/d/yyyy")) -> Naypyitaw_2/25/2019 | J22: =IF(Sheet1!I22=Sheet1!N22*0.05,"Valid","Error") -> Valid | K22: =IF(Sheet1!N22=Sheet1!G22*Sheet1!H22,"True","False") -> True | L22: TRUE | M22: =ISNUMBER(Sheet1!J22) -> TRUE | N22: =IF(Sheet1!B22="A","Branch A",IF(Sheet1!B22="B","Branch B","Other Branch")) -> Other Branch | O22: =IF(Sheet1!M22="Credit card","Credit Payment","Other") -> Other | P22: =IF(Sheet1!O22>7,"Yes","No") -> No
A23: 22 | B23: Return "Valid" if the Tax 5% equals 5% of cogs, otherwise return "Error". | E23: 371 | F23: 5789 | G23: 85 | H23: =_xlfn.CONCAT(Sheet1!A23," --> ",Sheet1!J23) -> 371-85-5789 --> 277.137 | I23: =_xlfn.CONCAT(Sheet1!C23,"_",TEXT(Sheet1!K23, "m/d/yyyy")) -> Mandalay_3/5/2019 | J23: =IF(Sheet1!I23=Sheet1!N23*0.05,"Valid","Error") -> Valid | K23: =IF(Sheet1!N23=Sheet1!G23*Sheet1!H23,"True","False") -> True | L23: TRUE | M23: =ISNUMBER(Sheet1!J23) -> TRUE | N23: =IF(Sheet1!B23="A","Branch A",IF(Sheet1!B23="B","Branch B","Other Branch")) -> Branch B | O23: =IF(Sheet1!M23="Credit card","Credit Payment","Other") -> Other | P23: =IF(Sheet1!O23>7,"Yes","No") -> No
A24: 23 | B24: Calculate the sum of Total for Product line "Fashion accessories". | C24: =SUMIF(Sheet1!F2:F1001,"Fashion accessories",Sheet1!J2:J1001) -> 54305.895 | E24: 273 | F24: 6619 | G24: 16 | H24: =_xlfn.CONCAT(Sheet1!A24," --> ",Sheet1!J24) -> 273-16-6619 --> 69.72 | I24: =_xlfn.CONCAT(Sheet1!C24,"_",TEXT(Sheet1!K24, "m/d/yyyy")) -> Mandalay_3/15/2019 | J24: =IF(Sheet1!I24=Sheet1!N24*0.05,"Valid","Error") -> Valid | K24: =IF(Sheet1!N24=Sheet1!G24*Sheet1!H24,"True","False") -> True | L24: TRUE | M24: =ISNUMBER(Sheet1!J24) -> TRUE | N24: =IF(Sheet1!B24="A","Branch A",IF(Sheet1!B24="B","Branch B","Other Branch")) -> Branch B | O24: =IF(Sheet1!M24="Credit card","Credit Payment","Other") -> Credit Payment | P24: =IF(Sheet1!O24>7,"Yes","No") -> No
A25: 24 | B25: Compute the average Rating for Branch "B". | C25: =AVERAGEIF(Sheet1!B2:B1001,"B",Sheet1!O2:O1001) -> 6.8180723 | E25: 636 | F25: 8204 | G25: 48 | H25: =_xlfn.CONCAT(Sheet1!A25," --> ",Sheet1!J25) -> 636-48-8204 --> 181.44 | I25: =_xlfn.CONCAT(Sheet1!C25,"_",TEXT(Sheet1!K25, "m/d/yyyy")) -> Yangon_2/17/2019 | J25: =IF(Sheet1!I25=Sheet1!N25*0.05,"Valid","Error") -> Valid | K25: =IF(Sheet1!N25=Sheet1!G25*Sheet1!H25,"True","False") -> True | L25: TRUE | M25: =ISNUMBER(Sheet1!J25) -> TRUE | N25: =IF(Sheet1!B25="A","Branch A",IF(Sheet1!B25="B","Branch B","Other Branch")) -> Branch A | O25: =IF(Sheet1!M25="Credit card","Credit Payment","Other") -> Other | P25: =IF(Sheet1!O25>7,"Yes","No") -> Yes
A26: 25 | B26: Count the number of transactions for Customer type "Member". | C26: =COUNTIF(Sheet1!D2:D1001,"Member") -> 501 | E26: 549 | F26: 1358 | G26: 59 | H26: =_xlfn.CONCAT(Sheet1!A26," --> ",Sheet1!J26) -> 549-59-1358 --> 279.1845 | I26: =_xlfn.CONCAT(Sheet1!C26,"_",TEXT(Sheet1!K26, "m/d/yyyy")) -> Yangon_3/2/2019 | J26: =IF(Sheet1!I26=Sheet1!N26*0.05,"Valid","Error") -> Valid | K26: =IF(Sheet1!N26=Sheet1!G26*Sheet1!H26,"True","False") -> True | L26: TRUE | M26: =ISNUMBER(Sheet1!J26) -> TRUE | N26: =IF(Sheet1!B26="A","Branch A",IF(Sheet1!B26="B","Branch B","Other Branch")) -> Branch A | O26: =IF(Sheet1!M26="Credit card","Credit Payment","Other") -> Other | P26: =IF(Sheet1!O26>7,"Yes","No") -> No
A27: 26 | B27: Calculate the total cogs for Gender "Female". | C27: =SUMIF(Sheet1!E2:E1001,"Female",Sheet1!N2:N1001) -> 159888.5 | E27: 227 | F27: 5010 | G27: 03 | H27: =_xlfn.CONCAT(Sheet1!A27," --> ",Sheet1!J27) -> 227-03-5010 --> 441.756 | I27: =_xlfn.CONCAT(Sheet1!C27,"_",TEXT(Sheet1!K27, "m/d/yyyy")) -> Yangon_3/22/2019 | J27: =IF(Sheet1!I27=Sheet1!N27*0.05,"Valid","Error") -> Valid | K27: =IF(Sheet1!N27=Sheet1!G27*Sheet1!H27,"True","False") -> True | L27: TRUE | M27: =ISNUMBER(Sheet1!J27) -> TRUE | N27: =IF(Sheet1!B27="A","Branch A",IF(Sheet1!B27="B","Branch B","Other Branch")) -> Branch A | O27: =IF(Sheet1!M27="Credit card","Credit Payment","Other") -> Credit Payment | P27: =IF(Sheet1!O27>7,"Yes","No") -> Yes
A28: 27 | B28: Check if cogs equals Unit price multiplied by Quantity (True/False). | E28: 649 | F28: 6775 | G28: 29 | H28: =_xlfn.CONCAT(Sheet1!A28," --> ",Sheet1!J28) -> 649-29-6775 --> 35.196 | I28: =_xlfn.CONCAT(Sheet1!C28,"_",TEXT(Sheet1!K28, "m/d/yyyy")) -> Mandalay_2/8/2019 | J28: =IF(Sheet1!I28=Sheet1!N28*0.05,"Valid","Error") -> Valid | K28: =IF(Sheet1!N28=Sheet1!G28*Sheet1!H28,"True","False") -> True | L28: TRUE | M28: =ISNUMBER(Sheet1!J28) -> TRUE | N28: =IF(Sheet1!B28="A","Branch A",IF(Sheet1!B28="B","Branch B","Other Branch")) -> Branch B | O28: =IF(Sheet1!M28="Credit card","Credit Payment","Other") -> Other | P28: =IF(Sheet1!O28>7,"Yes","No") -> No
A29: 28 | B29: Check if the City column contains text values. | E29: 189 | F29: 4241 | G29: 17 | H29: =_xlfn.CONCAT(Sheet1!A29," --> ",Sheet1!J29) -> 189-17-4241 --> 184.107 | I29: =_xlfn.CONCAT(Sheet1!C29,"_",TEXT(Sheet1!K29, "m/d/yyyy")) -> Yangon_3/10/2019 | J29: =IF(Sheet1!I29=Sheet1!N29*0.05,"Valid","Error") -> Valid | K29: =IF(Sheet1!N29=Sheet1!G29*Sheet1!H29,"True","False") -> True | L29: TRUE | M29: =ISNUMBER(Sheet1!J29) -> TRUE | N29: =IF(Sheet1!B29="A","Branch A",IF(Sheet1!B29="B","Branch B","Other Branch")) -> Branch A | O29: =IF(Sheet1!M29="Credit card","Credit Payment","Other") -> Credit Payment | P29: =IF(Sheet1!O29>7,"Yes","No") -> Yes
A30: 29 | B30: Total column are numeric. | E30: 145 | F30: 9061 | G30: 94 | H30: =_xlfn.CONCAT(Sheet1!A30," --> ",Sheet1!J30) -> 145-94-9061 --> 463.89 | I30: =_xlfn.CONCAT(Sheet1!C30,"_",TEXT(Sheet1!K30, "m/d/yyyy")) -> Mandalay_1/25/2019 | J30: =IF(Sheet1!I30=Sheet1!N30*0.05,"Valid","Error") -> Valid | K30: =IF(Sheet1!N30=Sheet1!G30*Sheet1!H30,"True","False") -> True | L30: TRUE | M30: =ISNUMBER(Sheet1!J30) -> TRUE | N30: =IF(Sheet1!B30="A","Branch A",IF(Sheet1!B30="B","Branch B","Other Branch")) -> Branch B | O30: =IF(Sheet1!M30="Credit card","Credit Payment","Other") -> Other | P30: =IF(Sheet1!O30>7,"Yes","No") -> Yes
A31: 30 | B31: Count the total number of transactions. | C31: =COUNT(Sheet1!J2:J1001) -> 1000 | E31: 848 | F31: 7243 | G31: 62 | H31: =_xlfn.CONCAT(Sheet1!A31," --> ",Sheet1!J31) -> 848-62-7243 --> 235.2105 | I31: =_xlfn.CONCAT(Sheet1!C31,"_",TEXT(Sheet1!K31, "m/d/yyyy")) -> Yangon_3/15/2019 | J31: =IF(Sheet1!I31=Sheet1!N31*0.05,"Valid","Error") -> Valid | K31: =IF(Sheet1!N31=Sheet1!G31*Sheet1!H31,"True","False") -> True | L31: TRUE | M31: =ISNUMBER(Sheet1!J31) -> TRUE | N31: =IF(Sheet1!B31="A","Branch A",IF(Sheet1!B31="B","Branch B","Other Branch")) -> Branch A | O31: =IF(Sheet1!M31="Credit card","Credit Payment","Other") -> Other | P31: =IF(Sheet1!O31>7,"Yes","No") -> Yes
A32: 31 | B32: Identify whether the Branch is "A" (return "Branch A") or not (return "Other Branch"). | E32: 871 | F32: 8483 | G32: 79 | H32: =_xlfn.CONCAT(Sheet1!A32," --> ",Sheet1!J32) -> 871-79-8483 --> 494.1825 | I32: =_xlfn.CONCAT(Sheet1!C32,"_",TEXT(Sheet1!K32, "m/d/yyyy")) -> Mandalay_2/25/2019 | J32: =IF(Sheet1!I32=Sheet1!N32*0.05,"Valid","Error") -> Valid | K32: =IF(Sheet1!N32=Sheet1!G32*Sheet1!H32,"True","False") -> True | L32: TRUE | M32: =ISNUMBER(Sheet1!J32) -> TRUE | N32: =IF(Sheet1!B32="A","Branch A",IF(Sheet1!B32="B","Branch B","Other Branch")) -> Branch B | O32: =IF(Sheet1!M32="Credit card","Credit Payment","Other") -> Credit Payment | P32: =IF(Sheet1!O32>7,"Yes","No") -> No
A33: 32 | B33: Check if the Payment method is "Credit card" and return "Card Payment" or "Other". | E33: 149 | F33: 6266 | G33: 71 | H33: =_xlfn.CONCAT(Sheet1!A33," --> ",Sheet1!J33) -> 149-71-6266 --> 737.7615 | I33: =_xlfn.CONCAT(Sheet1!C33,"_",TEXT(Sheet1!K33, "m/d/yyyy")) -> Mandalay_1/28/2019 | J33: =IF(Sheet1!I33=Sheet1!N33*0.05,"Valid","Error") -> Valid | K33: =IF(Sheet1!N33=Sheet1!G33*Sheet1!H33,"True","False") -> True | L33: TRUE | M33: =ISNUMBER(Sheet1!J33) -> TRUE | N33: =IF(Sheet1!B33="A","Branch A",IF(Sheet1!B33="B","Branch B","Other Branch")) -> Branch B | O33: =IF(Sheet1!M33="Credit card","Credit Payment","Other") -> Other | P33: =IF(Sheet1!O33>7,"Yes","No") -> No
A34: 33 | B34: Create a column to check if the Rating is greater than 7 (Yes/No). | E34: 640 | F34: 2076 | G34: 49 | H34: =_xlfn.CONCAT(Sheet1!A34," --> ",Sheet1!J34) -> 640-49-2076 --> 703.752 | I34: =_xlfn.CONCAT(Sheet1!C34,"_",TEXT(Sheet1!K34, "m/d/yyyy")) -> Mandalay_1/10/2019 | J34: =IF(Sheet1!I34=Sheet1!N34*0.05,"Valid","Error") -> Valid | K34: =IF(Sheet1!N34=Sheet1!G34*Sheet1!H34,"True","False") -> True | L34: TRUE | M34: =ISNUMBER(Sheet1!J34) -> TRUE | N34: =IF(Sheet1!B34="A","Branch A",IF(Sheet1!B34="B","Branch B","Other Branch")) -> Branch B | O34: =IF(Sheet1!M34="Credit card","Credit Payment","Other") -> Other | P34: =IF(Sheet1!O34>7,"Yes","No") -> No
E35: 595 | F35: 5460 | G35: 11 | H35: =_xlfn.CONCAT(Sheet1!A35," --> ",Sheet1!J35) -> 595-11-5460 --> 202.818 | I35: =_xlfn.CONCAT(Sheet1!C35,"_",TEXT(Sheet1!K35, "m/d/yyyy")) -> Yangon_3/15/2019 | J35: =IF(Sheet1!I35=Sheet1!N35*0.05,"Valid","Error") -> Valid | K35: =IF(Sheet1!N35=Sheet1!G35*Sheet1!H35,"True","False") -> True | L35: TRUE | M35: =ISNUMBER(Sheet1!J35) -> TRUE | N35: =IF(Sheet1!B35="A","Branch A",IF(Sheet1!B35="B","Branch B","Other Branch")) -> Branch A | O35: =IF(Sheet1!M35="Credit card","Credit Payment","Other") -> Credit Payment | P35: =IF(Sheet1!O35>7,"Yes","No") -> No
E36: 183 | F36: 6882 | G36: 56 | H36: =_xlfn.CONCAT(Sheet1!A36," --> ",Sheet1!J36) -> 183-56-6882 --> 417.564 | I36: =_xlfn.CONCAT(Sheet1!C36,"_",TEXT(Sheet1!K36, "m/d/yyyy")) -> Naypyitaw_2/6/2019 | J36: =IF(Sheet1!I36=Sheet1!N36*0.05,"Valid","Error") -> Valid | K36: =IF(Sheet1!N36=Sheet1!G36*Sheet1!H36,"True","False") -> True | L36: TRUE | M36: =ISNUMBER(Sheet1!J36) -> TRUE | N36: =IF(Sheet1!B36="A","Branch A",IF(Sheet1!B36="B","Branch B","Other Branch")) -> Other Branch | O36: =IF(Sheet1!M36="Credit card","Credit Payment","Other") -> Other | P36: =IF(Sheet1!O36>7,"Yes","No") -> Yes
E37: 232 | F37: 2483 | G37: 16 | H37: =_xlfn.CONCAT(Sheet1!A37," --> ",Sheet1!J37) -> 232-16-2483 --> 71.526 | I37: =_xlfn.CONCAT(Sheet1!C37,"_",TEXT(Sheet1!K37, "m/d/yyyy")) -> Naypyitaw_1/7/2019 | J37: =IF(Sheet1!I37=Sheet1!N37*0.05,"Valid","Error") -> Valid | K37: =IF(Sheet1!N37=Sheet1!G37*Sheet1!H37,"True","False") -> True | L37: TRUE | M37: =ISNUMBER(Sheet1!J37) -> TRUE | N37: =IF(Sheet1!B37="A","Branch A",IF(Sheet1!B37="B","Branch B","Other Branch")) -> Other Branch | O37: =IF(Sheet1!M37="Credit card","Credit Payment","Other") -> Other | P37: =IF(Sheet1!O37>7,"Yes","No") -> No
E38: 129 | F38: 8530 | G38: 29 | H38: =_xlfn.CONCAT(Sheet1!A38," --> ",Sheet1!J38) -> 129-29-8530 --> 328.755 | I38: =_xlfn.CONCAT(Sheet1!C38,"_",TEXT(Sheet1!K38, "m/d/yyyy")) -> Yangon_3/10/2019 | J38: =IF(Sheet1!I38=Sheet1!N38*0.05,"Valid","Error") -> Valid | K38: =IF(Sheet1!N38=Sheet1!G38*Sheet1!H38,"True","False") -> True | L38: TRUE | M38: =ISNUMBER(Sheet1!J38) -> TRUE | N38: =IF(Sheet1!B38="A","Branch A",IF(Sheet1!B38="B","Branch B","Other Branch")) -> Branch A | O38: =IF(Sheet1!M38="Credit card","Credit Payment","Other") -> Other | P38: =IF(Sheet1!O38>7,"Yes","No") -> No
E39: 272 | F39: 1806 | G39: 65 | H39: =_xlfn.CONCAT(Sheet1!A39," --> ",Sheet1!J39) -> 272-65-1806 --> 575.316 | I39: =_xlfn.CONCAT(Sheet1!C39,"_",TEXT(Sheet1!K39, "m/d/yyyy")) -> Yangon_1/15/2019 | J39: =IF(Sheet1!I39=Sheet1!N39*0.05,"Valid","Error") -> Valid | K39: =IF(Sheet1!N39=Sheet1!G39*Sheet1!H39,"True","False") -> True | L39: TRUE | M39: =ISNUMBER(Sheet1!J39) -> TRUE | N39: =IF(Sheet1!B39="A","Branch A",IF(Sheet1!B39="B","Branch B","Other Branch")) -> Branch A | O39: =IF(Sheet1!M39="Credit card","Credit Payment","Other") -> Other | P39: =IF(Sheet1!O39>7,"Yes","No") -> No
E40: 333 | F40: 7901 | G40: 73 | H40: =_xlfn.CONCAT(Sheet1!A40," --> ",Sheet1!J40) -> 333-73-7901 --> 461.328 | I40: =_xlfn.CONCAT(Sheet1!C40,"_",TEXT(Sheet1!K40, "m/d/yyyy")) -> Naypyitaw_3/23/2019 | J40: =IF(Sheet1!I40=Sheet1!N40*0.05,"Valid","Error") -> Valid | K40: =IF(Sheet1!N40=Sheet1!G40*Sheet1!H40,"True","False") -> True | L40: TRUE | M40: =ISNUMBER(Sheet1!J40) -> TRUE | N40: =IF(Sheet1!B40="A","Branch A",IF(Sheet1!B40="B","Branch B","Other Branch")) -> Other Branch | O40: =IF(Sheet1!M40="Credit card","Credit Payment","Other") -> Other | P40: =IF(Sheet1!O40>7,"Yes","No") -> Yes
...
