Workbook
Name Slicer_MONTH: #N/A
Name Slicer_Region: #N/A

Sheet Input Data
A1: DATE | B1: CUSTOMER NAME | C1: PRODUCT | D1: UNIT PRICE ($) | E1: QUANTITY | F1: SALES | G1: MONTH | H1: WEEK
A2: 44197 | B2: Customer33 | C2: Product24 | D2: 156.96 | E2: 9 | F2: =InputData[[#This Row],[UNIT PRICE ($)]]*InputData[[#This Row],[QUANTITY]] -> 1412.64 | G2: =TEXT(InputData[[#This Row],[DATE]],"mmm") -> Jan | H2: =WEEKNUM(InputData[[#This Row],[DATE]],1) -> 1
A3: 44197 | B3: Customer29 | C3: Product22 | D3: 141.57 | E3: 1 | F3: =InputData[[#This Row],[UNIT PRICE ($)]]*InputData[[#This Row],[QUANTITY]] -> 141.57 | G3: =TEXT(InputData[[#This Row],[DATE]],"mmm") -> Jan | H3: =WEEKNUM(InputData[[#This Row],[DATE]],1) -> 1
A4: 44198 | B4: Customer31 | C4: Product38 | D4: 79.92 | E4: 15 | F4: =InputData[[#This Row],[UNIT PRICE ($)]]*InputData[[#This Row],[QUANTITY]] -> 1198.8 | G4: =TEXT(InputData[[#This Row],[DATE]],"mmm") -> Jan | H4: =WEEKNUM(InputData[[#This Row],[DATE]],1) -> 1
A5: 44198 | B5: Customer03 | C5: Product33 | D5: 119.7 | E5: 1 | F5: =InputData[[#This Row],[UNIT PRICE ($)]]*InputData[[#This Row],[QUANTITY]] -> 119.7 | G5: =TEXT(InputData[[#This Row],[DATE]],"mmm") -> Jan | H5: =WEEKNUM(InputData[[#This Row],[DATE]],1) -> 1
A6: 44198 | B6: Customer05 | C6: Product15 | D6: 15.72 | E6: 2 | F6: =InputData[[#This Row],[UNIT PRICE ($)]]*InputData[[#This Row],[QUANTITY]] -> 31.44 | G6: =TEXT(InputData[[#This Row],[DATE]],"mmm") -> Jan | H6: =WEEKNUM(InputData[[#This Row],[DATE]],1) -> 1
A7: 44198 | B7: Customer35 | C7: Product10 | D7: 164.28 | E7: 7 | F7: =InputData[[#This Row],[UNIT PRICE ($)]]*InputData[[#This Row],[QUANTITY]] -> 1149.96 | G7: =TEXT(InputData[[#This Row],[DATE]],"mmm") -> Jan | H7: =WEEKNUM(InputData[[#This Row],[DATE]],1) -> 1
A8: 44198 | B8: Customer38 | C8: Product13 | D8: 122.08 | E8: 6 | F8: =InputData[[#This Row],[UNIT PRICE ($)]]*InputData[[#This Row],[QUANTITY]] -> 732.48 | G8: =TEXT(InputData[[#This Row],[DATE]],"mmm") -> Jan | H8: =WEEKNUM(InputData[[#This Row],[DATE]],1) -> 1
A9: 44198 | B9: Customer39 | C9: Product15 | D9: 15.72 | E9: 25 | F9: =InputData[[#This Row],[UNIT PRICE ($)]]*InputData[[#This Row],[QUANTITY]] -> 393 | G9: =TEXT(InputData[[#This Row],[DATE]],"mmm") -> Jan | H9: =WEEKNUM(InputData[[#This Row],[DATE]],1) -> 1
A10: 44199 | B10: Customer34 | C10: Product14 | D10: 146.72 | E10: 21 | F10: =InputData[[#This Row],[UNIT PRICE ($)]]*InputData[[#This Row],[QUANTITY]] -> 3081.12 | G10: =TEXT(InputData[[#This Row],[DATE]],"mmm") -> Jan | H10: =WEEKNUM(InputData[[#This Row],[DATE]],1) -> 2
A11: 44199 | B11: Customer18 | C11: Product43 | D11: 83.08 | E11: 9 | F11: =InputData[[#This Row],[UNIT PRICE ($)]]*InputData[[#This Row],[QUANTITY]] -> 747.72 | G11: =TEXT(InputData[[#This Row],[DATE]],"mmm") -> Jan | H11: =WEEKNUM(InputData[[#This Row],[DATE]],1) -> 2
A12: 44199 | B12: Customer20 | C12: Product38 | D12: 79.92 | E12: 31 | F12: =InputData[[#This Row],[UNIT PRICE ($)]]*InputData[[#This Row],[QUANTITY]] -> 2477.52 | G12: =TEXT(InputData[[#This Row],[DATE]],"mmm") -> Jan | H12: =WEEKNUM(InputData[[#This Row],[DATE]],1) -> 2
A13: 44199 | B13: Customer37 | C13: Product04 | D13: 48.84 | E13: 5 | F13: =InputData[[#This Row],[UNIT PRICE ($)]]*InputData[[#This Row],[QUANTITY]] -> 244.2 | G13: =TEXT(InputData[[#This Row],[DATE]],"mmm") -> Jan | H13: =WEEKNUM(InputData[[#This Row],[DATE]],1) -> 2
... A833: 44561 | B833: Customer18 | C833: Product33 | D833: 119.7 | E833: 12 | F833: =InputData[[#This Row],[UNIT PRICE ($)]]*InputData[[#This Row],[QUANTITY]] -> 1436.4 | G833: =TEXT(InputData[[#This Row],[DATE]],"mmm") -> Dec | H833: =WEEKNUM(InputData[[#This Row],[DATE]],1) -> 53

Sheet Target
A1: Month | B1: Month Name | C1: Target ($) | D1: Total Sales | E1: Below | F1: Above
A2: 1 | B2: Jan | C2: 90000 | D2: =SUMIFS(InputData[SALES],InputData[MONTH],TargetData[[#This Row],[Month Name]]) -> 92118.79 | E2: =IF(TargetData[[#This Row],[Total Sales]]<TargetData[[#This Row],[Target ($)]],TargetData[[#This Row],[Total Sales]],NA()) -> #N/A | F2: =IF(TargetData[[#This Row],[Total Sales]]>=TargetData[[#This Row],[Target ($)]],TargetData[[#This Row],[Total Sales]],NA()) -> 92118.79
A3: 2 | B3: Feb | C3: 100000 | D3: =SUMIFS(InputData[SALES],InputData[MONTH],TargetData[[#This Row],[Month Name]]) -> 91137.05 | E3: =IF(TargetData[[#This Row],[Total Sales]]<TargetData[[#This Row],[Target ($)]],TargetData[[#This Row],[Total Sales]],NA()) -> 91137.05 | F3: =IF(TargetData[[#This Row],[Total Sales]]>=TargetData[[#This Row],[Target ($)]],TargetData[[#This Row],[Total Sales]],NA()) -> #N/A
A4: 3 | B4: Mar | C4: 100000 | D4: =SUMIFS(InputData[SALES],InputData[MONTH],TargetData[[#This Row],[Month Name]]) -> 97920.72 | E4: =IF(TargetData[[#This Row],[Total Sales]]<TargetData[[#This Row],[Target ($)]],TargetData[[#This Row],[Total Sales]],NA()) -> 97920.72 | F4: =IF(TargetData[[#This Row],[Total Sales]]>=TargetData[[#This Row],[Target ($)]],TargetData[[#This Row],[Total Sales]],NA()) -> #N/A
A5: 4 | B5: Apr | C5: 100000 | D5: =SUMIFS(InputData[SALES],InputData[MONTH],TargetData[[#This Row],[Month Name]]) -> 72320.89 | E5: =IF(TargetData[[#This Row],[Total Sales]]<TargetData[[#This Row],[Target ($)]],TargetData[[#This Row],[Total Sales]],NA()) -> 72320.89 | F5: =IF(TargetData[[#This Row],[Total Sales]]>=TargetData[[#This Row],[Target ($)]],TargetData[[#This Row],[Total Sales]],NA()) -> #N/A
A6: 5 | B6: May | C6: 90000 | D6: =SUMIFS(InputData[SALES],InputData[MONTH],TargetData[[#This Row],[Month Name]]) -> 70511.76 | E6: =IF(TargetData[[#This Row],[Total Sales]]<TargetData[[#This Row],[Target ($)]],TargetData[[#This Row],[Total Sales]],NA()) -> 70511.76 | F6: =IF(TargetData[[#This Row],[Total Sales]]>=TargetData[[#This Row],[Target ($)]],TargetData[[#This Row],[Total Sales]],NA()) -> #N/A
A7: 6 | B7: Jun | C7: 90000 | D7: =SUMIFS(InputData[SALES],InputData[MONTH],TargetData[[#This Row],[Month Name]]) -> 66727.4 | E7: =IF(TargetData[[#This Row],[Total Sales]]<TargetData[[#This Row],[Target ($)]],TargetData[[#This Row],[Total Sales]],NA()) -> 66727.4 | F7: =IF(TargetData[[#This Row],[Total Sales]]>=TargetData[[#This Row],[Target ($)]],TargetData[[#This Row],[Total Sales]],NA()) -> #N/A
A8: 7 | B8: Jul | C8: 90000 | D8: =SUMIFS(InputData[SALES],InputData[MONTH],TargetData[[#This Row],[Month Name]]) -> 92661.55 | E8: =IF(TargetData[[#This Row],[Total Sales]]<TargetData[[#This Row],[Target ($)]],TargetData[[#This Row],[Total Sales]],NA()) -> #N/A | F8: =IF(TargetData[[#This Row],[Total Sales]]>=TargetData[[#This Row],[Target ($)]],TargetData[[#This Row],[Total Sales]],NA()) -> 92661.55
A9: 8 | B9: Aug | C9: 90000 | D9: =SUMIFS(InputData[SALES],InputData[MONTH],TargetData[[#This Row],[Month Name]]) -> 69125.75 | E9: =IF(TargetData[[#This Row],[Total Sales]]<TargetData[[#This Row],[Target ($)]],TargetData[[#This Row],[Total Sales]],NA()) -> 69125.75 | F9: =IF(TargetData[[#This Row],[Total Sales]]>=TargetData[[#This Row],[Target ($)]],TargetData[[#This Row],[Total Sales]],NA()) -> #N/A
A10: 9 | B10: Sep | C10: 90000 | D10: =SUMIFS(InputData[SALES],InputData[MONTH],TargetData[[#This Row],[Month Name]]) -> 78253.53 | E10: =IF(TargetData[[#This Row],[Total Sales]]<TargetData[[#This Row],[Target ($)]],TargetData[[#This Row],[Total Sales]],NA()) -> 78253.53 | F10: =IF(TargetData[[#This Row],[Total Sales]]>=TargetData[[#This Row],[Target ($)]],TargetData[[#This Row],[Total Sales]],NA()) -> #N/A
A11: 10 | B11: Oct | C11: 80000 | D11: =SUMIFS(InputData[SALES],InputData[MONTH],TargetData[[#This Row],[Month Name]]) -> 87136.37 | E11: =IF(TargetData[[#This Row],[Total Sales]]<TargetData[[#This Row],[Target ($)]],TargetData[[#This Row],[Total Sales]],NA()) -> #N/A | F11: =IF(TargetData[[#This Row],[Total Sales]]>=TargetData[[#This Row],[Target ($)]],TargetData[[#This Row],[Total Sales]],NA()) -> 87136.37
A12: 11 | B12: Nov | C12: 80000 | D12: =SUMIFS(InputData[SALES],InputData[MONTH],TargetData[[#This Row],[Month Name]]) -> 75659.86 | E12: =IF(TargetData[[#This Row],[Total Sales]]<TargetData[[#This Row],[Target ($)]],TargetData[[#This Row],[Total Sales]],NA()) -> 75659.86 | F12: =IF(TargetData[[#This Row],[Total Sales]]>=TargetData[[#This Row],[Target ($)]],TargetData[[#This Row],[Total Sales]],NA()) -> #N/A
A13: 12 | B13: Dec | C13: 80000 | D13: =SUMIFS(InputData[SALES],InputData[MONTH],TargetData[[#This Row],[Month Name]]) -> 90997.39 | E13: =IF(TargetData[[#This Row],[Total Sales]]<TargetData[[#This Row],[Target ($)]],TargetData[[#This Row],[Total Sales]],NA()) -> #N/A | F13: =IF(TargetData[[#This Row],[Total Sales]]>=TargetData[[#This Row],[Target ($)]],TargetData[[#This Row],[Total Sales]],NA()) -> 90997.39

Sheet Customer
A1: Customer Name | B1: Country | C1: Region | D1: Sales
A2: Customer01 | B2: Nigeria | C2: Export | D2: =_xlfn.XLOOKUP(Country[[#This Row],[Customer Name]],InputData[CUSTOMER NAME],InputData[SALES]) -> 1240.98
A3: Customer02 | B3: Bangladesh | C3: Export | D3: =_xlfn.XLOOKUP(Country[[#This Row],[Customer Name]],InputData[CUSTOMER NAME],InputData[SALES]) -> 1436.4
A4: Customer03 | B4: India | C4: Northeast | D4: =_xlfn.XLOOKUP(Country[[#This Row],[Customer Name]],InputData[CUSTOMER NAME],InputData[SALES]) -> 119.7
A5: Customer04 | B5: Saudi Arabia | C5: Export | D5: =_xlfn.XLOOKUP(Country[[#This Row],[Customer Name]],InputData[CUSTOMER NAME],InputData[SALES]) -> 840
A6: Customer05 | B6: India | C6: Northeast | D6: =_xlfn.XLOOKUP(Country[[#This Row],[Customer Name]],InputData[CUSTOMER NAME],InputData[SALES]) -> 31.44
A7: Customer06 | B7: Pakistan | C7: Export | D7: =_xlfn.XLOOKUP(Country[[#This Row],[Customer Name]],InputData[CUSTOMER NAME],InputData[SALES]) -> 1057.32
A8: Customer07 | B8: Indonesia | C8: Export | D8: =_xlfn.XLOOKUP(Country[[#This Row],[Customer Name]],InputData[CUSTOMER NAME],InputData[SALES]) -> 2464.2
A9: Customer08 | B9: United Kingdom | C9: Export | D9: =_xlfn.XLOOKUP(Country[[#This Row],[Customer Name]],InputData[CUSTOMER NAME],InputData[SALES]) -> 460.8
A10: Customer09 | B10: Russia | C10: Export | D10: =_xlfn.XLOOKUP(Country[[#This Row],[Customer Name]],InputData[CUSTOMER NAME],InputData[SALES]) -> 753.36
A11: Customer10 | B11: India | C11: South | D11: =_xlfn.XLOOKUP(Country[[#This Row],[Customer Name]],InputData[CUSTOMER NAME],InputData[SALES]) -> 47.16
A12: Customer11 | B12: Mexico | C12: Export | D12: =_xlfn.XLOOKUP(Country[[#This Row],[Customer Name]],InputData[CUSTOMER NAME],InputData[SALES]) -> 586.88
A13: Customer12 | B13: India | C13: Central | D13: =_xlfn.XLOOKUP(Country[[#This Row],[Customer Name]],InputData[CUSTOMER NAME],InputData[SALES]) -> 58.31
... A41: Customer40 | B41: United States of America | C41: Export | D41: =_xlfn.XLOOKUP(Country[[#This Row],[Customer Name]],InputData[CUSTOMER NAME],InputData[SALES]) -> 1670.55

Sheet Functions
B3: Week | C3: Total Sales | E3: Month | F3: Total Sales | G3: Target | I3: Total Sales | L3: Customer | M3: Total Sales | O3: Product | P3: Total Sales
B4: {=_xlfn.UNIQUE(InputData[WEEK])} -> 1 | C4: =_xlfn.XLOOKUP(B4,InputData[WEEK],InputData[SALES]) -> 1412.64 | E4: {=_xlfn.UNIQUE(InputData[MONTH])} -> Jan | F4: =_xlfn.XLOOKUP(E4,TargetData[Month Name],TargetData[Total Sales]) -> 92118.79 | G4: =_xlfn.XLOOKUP(E4,TargetData[Month Name],TargetData[Target ($)]) -> 90000 | I4: =SUM(InputData[SALES]) -> 984571.06 | L4: {=_xlfn.UNIQUE(InputData[CUSTOMER NAME])} -> Customer33 | M4: =SUMIFS(InputData[SALES],InputData[CUSTOMER NAME],Functions!L4) -> 60929.15 | O4: {=_xlfn.UNIQUE(InputData[PRODUCT])} -> Product24 | P4: =SUMIFS(InputData[SALES],InputData[PRODUCT],Functions!O4) -> 49599.36
B5: 2 | C5: =_xlfn.XLOOKUP(B5,InputData[WEEK],InputData[SALES]) -> 3081.12 | E5: Feb | F5: =_xlfn.XLOOKUP(E5,TargetData[Month Name],TargetData[Total Sales]) -> 91137.05 | G5: =_xlfn.XLOOKUP(E5,TargetData[Month Name],TargetData[Target ($)]) -> 100000 | L5: Customer29 | M5: =SUMIFS(InputData[SALES],InputData[CUSTOMER NAME],Functions!L5) -> 24862.52 | O5: Product22 | P5: =SUMIFS(InputData[SALES],InputData[PRODUCT],Functions!O5) -> 41055.3
B6: 3 | C6: =_xlfn.XLOOKUP(B6,InputData[WEEK],InputData[SALES]) -> 3427.2 | E6: Mar | F6: =_xlfn.XLOOKUP(E6,TargetData[Month Name],TargetData[Total Sales]) -> 97920.72 | G6: =_xlfn.XLOOKUP(E6,TargetData[Month Name],TargetData[Target ($)]) -> 100000 | L6: Customer31 | M6: =SUMIFS(InputData[SALES],InputData[CUSTOMER NAME],Functions!L6) -> 17704.34 | O6: Product38 | P6: =SUMIFS(InputData[SALES],InputData[PRODUCT],Functions!O6) -> 25574.4
B7: 4 | C7: =_xlfn.XLOOKUP(B7,InputData[WEEK],InputData[SALES]) -> 460.8 | E7: Apr | F7: =_xlfn.XLOOKUP(E7,TargetData[Month Name],TargetData[Total Sales]) -> 72320.89 | G7: =_xlfn.XLOOKUP(E7,TargetData[Month Name],TargetData[Target ($)]) -> 100000 | I7: Customer | J7: Total Sales | L7: Customer03 | M7: =SUMIFS(InputData[SALES],InputData[CUSTOMER NAME],Functions!L7) -> 7541.72 | O7: Product33 | P7: =SUMIFS(InputData[SALES],InputData[PRODUCT],Functions!O7) -> 22743
B8: 5 | C8: =_xlfn.XLOOKUP(B8,InputData[WEEK],InputData[SALES]) -> 3019.2 | E8: May | F8: =_xlfn.XLOOKUP(E8,TargetData[Month Name],TargetData[Total Sales]) -> 70511.76 | G8: =_xlfn.XLOOKUP(E8,TargetData[Month Name],TargetData[Target ($)]) -> 90000 | I8: {=_xlfn.XLOOKUP(J8,$M$4:$M$43,_xlfn.ANCHORARRAY($L$4))} -> Customer33 | J8: =LARGE($M$4:$M$43,1) -> 60929.15 | L8: Customer05 | M8: =SUMIFS(InputData[SALES],InputData[CUSTOMER NAME],Functions!L8) -> 23913.72 | O8: Product15 | P8: =SUMIFS(InputData[SALES],InputData[PRODUCT],Functions!O8) -> 3678.48
B9: 6 | C9: =_xlfn.XLOOKUP(B9,InputData[WEEK],InputData[SALES]) -> 1142.4 | E9: Jun | F9: =_xlfn.XLOOKUP(E9,TargetData[Month Name],TargetData[Total Sales]) -> 66727.4 | G9: =_xlfn.XLOOKUP(E9,TargetData[Month Name],TargetData[Target ($)]) -> 90000 | I9: {=_xlfn.XLOOKUP(J9,$M$4:$M$43,_xlfn.ANCHORARRAY($L$4))} -> Customer22 | J9: =LARGE($M$4:$M$43,2) -> 45112.95 | L9: Customer35 | M9: =SUMIFS(InputData[SALES],InputData[CUSTOMER NAME],Functions!L9) -> 13827.74 | O9: Product10 | P9: =SUMIFS(InputData[SALES],InputData[PRODUCT],Functions!O9) -> 34991.64
B10: 7 | C10: =_xlfn.XLOOKUP(B10,InputData[WEEK],InputData[SALES]) -> 194.3 | E10: Jul | F10: =_xlfn.XLOOKUP(E10,TargetData[Month Name],TargetData[Total Sales]) -> 92661.55 | G10: =_xlfn.XLOOKUP(E10,TargetData[Month Name],TargetData[Target ($)]) -> 90000 | I10: {=_xlfn.XLOOKUP(J10,$M$4:$M$43,_xlfn.ANCHORARRAY($L$4))} -> Customer23 | J10: =LARGE($M$4:$M$43,3) -> 43062.83 | L10: Customer38 | M10: =SUMIFS(InputData[SALES],InputData[CUSTOMER NAME],Functions!L10) -> 10119.97 | O10: Product13 | P10: =SUMIFS(InputData[SALES],InputData[PRODUCT],Functions!O10) -> 14039.2
B11: 8 | C11: =_xlfn.XLOOKUP(B11,InputData[WEEK],InputData[SALES]) -> 125.43 | E11: Aug | F11: =_xlfn.XLOOKUP(E11,TargetData[Month Name],TargetData[Total Sales]) -> 69125.75 | G11: =_xlfn.XLOOKUP(E11,TargetData[Month Name],TargetData[Target ($)]) -> 90000 | L11: Customer39 | M11: =SUMIFS(InputData[SALES],InputData[CUSTOMER NAME],Functions!L11) -> 16810.72 | O11: Product14 | P11: =SUMIFS(InputData[SALES],InputData[PRODUCT],Functions!O11) -> 23915.36
B12: 9 | C12: =_xlfn.XLOOKUP(B12,InputData[WEEK],InputData[SALES]) -> 1476.3 | E12: Sep | F12: =_xlfn.XLOOKUP(E12,TargetData[Month Name],TargetData[Total Sales]) -> 78253.53 | G12: =_xlfn.XLOOKUP(E12,TargetData[Month Name],TargetData[Target ($)]) -> 90000 | L12: Customer34 | M12: =SUMIFS(InputData[SALES],InputData[CUSTOMER NAME],Functions!L12) -> 10923.66 | O12: Product43 | P12: =SUMIFS(InputData[SALES],InputData[PRODUCT],Functions!O12) -> 16034.44
B13: 10 | C13: =_xlfn.XLOOKUP(B13,InputData[WEEK],InputData[SALES]) -> 1286.4 | E13: Oct | F13: =_xlfn.XLOOKUP(E13,TargetData[Month Name],TargetData[Total Sales]) -> 87136.37 | G13: =_xlfn.XLOOKUP(E13,TargetData[Month Name],TargetData[Target ($)]) -> 80000 | I13: Product | J13: Sales | L13: Customer18 | M13: =SUMIFS(InputData[SALES],InputData[CUSTOMER NAME],Functions!L13) -> 17789.41 | O13: Product04 | P13: =SUMIFS(InputData[SALES],InputData[PRODUCT],Functions!O13) -> 11428.56
B14: 11 | C14: =_xlfn.XLOOKUP(B14,InputData[WEEK],InputData[SALES]) -> 80.94 | E14: Nov | F14: =_xlfn.XLOOKUP(E14,TargetData[Month Name],TargetData[Total Sales]) -> 75659.86 | G14: =_xlfn.XLOOKUP(E14,TargetData[Month Name],TargetData[Target ($)]) -> 80000 | I14: {=_xlfn.XLOOKUP(J14,$P$4:$P$47,_xlfn.ANCHORARRAY($O$4))} -> Product30 | J14: =LARGE($P$4:$P$47,1) -> 57968.64 | L14: Customer20 | M14: =SUMIFS(InputData[SALES],InputData[CUSTOMER NAME],Functions!L14) -> 26437.86 | O14: Product29 | P14: =SUMIFS(InputData[SALES],InputData[PRODUCT],Functions!O14) -> 8232.05
B15: 12 | C15: =_xlfn.XLOOKUP(B15,InputData[WEEK],InputData[SALES]) -> 2123.55 | E15: Dec | F15: =_xlfn.XLOOKUP(E15,TargetData[Month Name],TargetData[Total Sales]) -> 90997.39 | G15: =_xlfn.XLOOKUP(E15,TargetData[Month Name],TargetData[Target ($)]) -> 80000 | I15: {=_xlfn.XLOOKUP(J15,$P$4:$P$47,_xlfn.ANCHORARRAY($O$4))} -> Product41 | J15: =LARGE($P$4:$P$47,2) -> 57554.28 | L15: Customer37 | M15: =SUMIFS(InputData[SALES],InputData[CUSTOMER NAME],Functions!L15) -> 5519.83 | O15: Product12 | P15: =SUMIFS(InputData[SALES],InputData[PRODUCT],Functions!O15) -> 21470.76
B16: 13 | C16: =_xlfn.XLOOKUP(B16,InputData[WEEK],InputData[SALES]) -> 297.85 | I16: {=_xlfn.XLOOKUP(J16,$P$4:$P$47,_xlfn.ANCHORARRAY($O$4))} -> Product24 | J16: =LARGE($P$4:$P$47,3) -> 49599.36 | L16: Customer32 | M16: =SUMIFS(InputData[SALES],InputData[CUSTOMER NAME],Functions!L16) -> 16119.88 | O16: Product35 | P16: =SUMIFS(InputData[SALES],InputData[PRODUCT],Functions!O16) -> 2365.1
B17: 14 | C17: =_xlfn.XLOOKUP(B17,InputData[WEEK],InputData[SALES]) -> 1497.6 | I17: {=_xlfn.XLOOKUP(J17,$P$4:$P$47,_xlfn.ANCHORARRAY($O$4))} -> Product19 | J17: =LARGE($P$4:$P$47,4) -> 41580 | L17: Customer09 | M17: =SUMIFS(InputData[SALES],InputData[CUSTOMER NAME],Functions!L17) -> 24159.03 | O17: Product32 | P17: =SUMIFS(InputData[SALES],InputData[PRODUCT],Functions!O17) -> 40883.04
B18: 15 | C18: =_xlfn.XLOOKUP(B18,InputData[WEEK],InputData[SALES]) -> 70.74 | E18: Region | F18: Total Sales | I18: {=_xlfn.XLOOKUP(J18,$P$4:$P$47,_xlfn.ANCHORARRAY($O$4))} -> Product22 | J18: =LARGE($P$4:$P$47,5) -> 41055.3 | L18: Customer26 | M18: =SUMIFS(InputData[SALES],InputData[CUSTOMER NAME],Functions!L18) -> 31495.42 | O18: Product19 | P18: =SUMIFS(InputData[SALES],InputData[PRODUCT],Functions!O18) -> 41580
B19: 16 | C19: =_xlfn.XLOOKUP(B19,InputData[WEEK],InputData[SALES]) -> 62.88 | E19: {=_xlfn.UNIQUE(Country[Region])} -> Export | F19: =SUMIFS(Country[Sales],Country[Region],Functions!E19) -> 23052.08 | I19: {=_xlfn.XLOOKUP(J19,$P$4:$P$47,_xlfn.ANCHORARRAY($O$4))} -> Product32 | J19: =LARGE($P$4:$P$47,6) -> 40883.04 | L19: Customer06 | M19: =SUMIFS(InputData[SALES],InputData[CUSTOMER NAME],Functions!L19) -> 33252.92 | O19: Product07 | P19: =SUMIFS(InputData[SALES],InputData[PRODUCT],Functions!O19) -> 6682.2
B20: 17 | C20: =_xlfn.XLOOKUP(B20,InputData[WEEK],InputData[SALES]) -> 1564.92 | E20: Northeast | F20: =SUMIFS(Country[Sales],Country[Region],Functions!E20) -> 4045.14 | I20: {=_xlfn.XLOOKUP(J20,$P$4:$P$47,_xlfn.ANCHORARRAY($O$4))} -> Product21 | J20: =LARGE($P$4:$P$47,7) -> 39659.76 | L20: Customer01 | M20: =SUMIFS(InputData[SALES],InputData[CUSTOMER NAME],Functions!L20) -> 39993.27 | O20: Product31 | P20: =SUMIFS(InputData[SALES],InputData[PRODUCT],Functions!O20) -> 17498.88
B21: 18 | C21: =_xlfn.XLOOKUP(B21,InputData[WEEK],InputData[SALES]) -> 647.52 | E21: South | F21: =SUMIFS(Country[Sales],Country[Region],Functions!E21) -> 812.01 | I21: {=_xlfn.XLOOKUP(J21,$P$4:$P$47,_xlfn.ANCHORARRAY($O$4))} -> Product05 | J21: =LARGE($P$4:$P$47,8) -> 38591.28 | L21: Customer16 | M21: =SUMIFS(InputData[SALES],InputData[CUSTOMER NAME],Functions!L21) -> 39185.31 | O21: Product25 | P21: =SUMIFS(InputData[SALES],InputData[PRODUCT],Functions!O21) -> 2115.82
B22: 19 | C22: =_xlfn.XLOOKUP(B22,InputData[WEEK],InputData[SALES]) -> 488.32 | E22: Central | F22: =SUMIFS(Country[Sales],Country[Region],Functions!E22) -> 3283.91 | I22: {=_xlfn.XLOOKUP(J22,$P$4:$P$47,_xlfn.ANCHORARRAY($O$4))} -> Product42 | J22: =LARGE($P$4:$P$47,9) -> 38232 | L22: Customer19 | M22: =SUMIFS(InputData[SALES],InputData[CUSTOMER NAME],Functions!L22) -> 38673.03 | O22: Product40 | P22: =SUMIFS(InputData[SALES],InputData[PRODUCT],Functions!O22) -> 32140.8
B23: 20 | C23: =_xlfn.XLOOKUP(B23,InputData[WEEK],InputData[SALES]) -> 334.48 | E23: East | F23: =SUMIFS(Country[Sales],Country[Region],Functions!E23) -> 2280.87 | I23: {=_xlfn.XLOOKUP(J23,$P$4:$P$47,_xlfn.ANCHORARRAY($O$4))} -> Product10 | J23: =LARGE($P$4:$P$47,10) -> 34991.64 | L23: Customer36 | M23: =SUMIFS(InputData[SALES],InputData[CUSTOMER NAME],Functions!L23) -> 28150.48 | O23: Product03 | P23: =SUMIFS(InputData[SALES],InputData[PRODUCT],Functions!O23) -> 17563.98
B24: 21 | C24: =_xlfn.XLOOKUP(B24,InputData[WEEK],InputData[SALES]) -> 2135.64 | E24: Western | F24: =SUMIFS(Country[Sales],Country[Region],Functions!E24) -> 3414.6 | L24: Customer21 | M24: =SUMIFS(InputData[SALES],InputData[CUSTOMER NAME],Functions!L24) -> 32808.02 | O24: Product02 | P24: =SUMIFS(InputData[SALES],InputData[PRODUCT],Functions!O24) -> 30987.6
B25: 22 | C25: =_xlfn.XLOOKUP(B25,InputData[WEEK],InputData[SALES]) -> 1267.2 | E25: North | F25: =SUMIFS(Country[Sales],Country[Region],Functions!E25) -> 3415.8 | L25: Customer11 | M25: =SUMIFS(InputData[SALES],InputData[CUSTOMER NAME],Functions!L25) -> 30344.9 | O25: Product34 | P25: =SUMIFS(InputData[SALES],InputData[PRODUCT],Functions!O25) -> 15332.9
B26: 23 | C26: =_xlfn.XLOOKUP(B26,InputData[WEEK],InputData[SALES]) -> 622.44 | L26: Customer17 | M26: =SUMIFS(InputData[SALES],InputData[CUSTOMER NAME],Functions!L26) -> 16605.59 | O26: Product37 | P26: =SUMIFS(InputData[SALES],InputData[PRODUCT],Functions!O26) -> 17752.32
B27: 24 | C27: =_xlfn.XLOOKUP(B27,InputData[WEEK],InputData[SALES]) -> 718.2 | L27: Customer14 | M27: =SUMIFS(InputData[SALES],InputData[CUSTOMER NAME],Functions!L27) -> 30826.78 | O27: Product11 | P27: =SUMIFS(InputData[SALES],InputData[PRODUCT],Functions!O27) -> 14084.4
B28: 25 | C28: =_xlfn.XLOOKUP(B28,InputData[WEEK],InputData[SALES]) -> 147.96 | E28: Country | F28: Total Sales | L28: Customer08 | M28: =SUMIFS(InputData[SALES],InputData[CUSTOMER NAME],Functions!L28) -> 24311.18 | O28: Product42 | P28: =SUMIFS(InputData[SALES],InputData[PRODUCT],Functions!O28) -> 38232
B29: 26 | C29: =_xlfn.XLOOKUP(B29,InputData[WEEK],InputData[SALES]) -> 16.64 | E29: {=_xlfn.UNIQUE(Country[Country])} -> Nigeria | F29: =SUMIFS(Country[Sales],Country[Country],Functions!E29) -> 1240.98 | L29: Customer24 | M29: =SUMIFS(InputData[SALES],InputData[CUSTOMER NAME],Functions!L29) -> 13549.7 | O29: Product16 | P29: =SUMIFS(InputData[SALES],InputData[PRODUCT],Functions!O29) -> 6206.72
B30: 27 | C30: =_xlfn.XLOOKUP(B30,InputData[WEEK],InputData[SALES]) -> 1711.71 | E30: Bangladesh | F30: =SUMIFS(Country[Sales],Country[Country],Functions!E30) -> 1436.4 | L30: Customer25 | M30: =SUMIFS(InputData[SALES],InputData[CUSTOMER NAME],Functions!L30) -> 39653.93 | O30: Product08 | P30: =SUMIFS(InputData[SALES],InputData[PRODUCT],Functions!O30) -> 23749.62
B31: 28 | C31: =_xlfn.XLOOKUP(B31,InputData[WEEK],InputData[SALES]) -> 334.11 | E31: India | F31: =SUMIFS(Country[Sales],Country[Country],Functions!E31) -> 17252.33 | L31: Customer27 | M31: =SUMIFS(InputData[SALES],InputData[CUSTOMER NAME],Functions!L31) -> 14192.22 | O31: Product23 | P31: =SUMIFS(InputData[SALES],InputData[PRODUCT],Functions!O31) -> 19280.34
B32: 29 | C32: =_xlfn.XLOOKUP(B32,InputData[WEEK],InputData[SALES]) -> 31.44 | E32: Saudi Arabia | F32: =SUMIFS(Country[Sales],Country[Country],Functions!E32) -> 1488 | L32: Customer15 | M32: =SUMIFS(InputData[SALES],InputData[CUSTOMER NAME],Functions!L32) -> 33187.04 | O32: Product44 | P32: =SUMIFS(InputData[SALES],InputData[PRODUCT],Functions!O32) -> 23556.96
B33: 30 | C33: =_xlfn.XLOOKUP(B33,InputData[WEEK],InputData[SALES]) -> 799.68 | E33: Pakistan | F33: =SUMIFS(Country[Sales],Country[Country],Functions!E33) -> 2520.19 | L33: Customer22 | M33: =SUMIFS(InputData[SALES],InputData[CUSTOMER NAME],Functions!L33) -> 45112.95 | O33: Product20 | P33: =SUMIFS(InputData[SALES],InputData[PRODUCT],Functions!O33) -> 13267.5
B34: 31 | C34: =_xlfn.XLOOKUP(B34,InputData[WEEK],InputData[SALES]) -> 1052.22 | E34: Indonesia | F34: =SUMIFS(Country[Sales],Country[Country],Functions!E34) -> 2464.2 | L34: Customer30 | M34: =SUMIFS(InputData[SALES],InputData[CUSTOMER NAME],Functions!L34) -> 35431.86 | O34: Product21 | P34: =SUMIFS(InputData[SALES],InputData[PRODUCT],Functions!O34) -> 39659.76
B35: 32 | C35: =_xlfn.XLOOKUP(B35,InputData[WEEK],InputData[SALES]) -> 1142.68 | E35: United Kingdom | F35: =SUMIFS(Country[Sales],Country[Country],Functions!E35) -> 2938.32 | L35: Customer04 | M35: =SUMIFS(InputData[SALES],InputData[CUSTOMER NAME],Functions!L35) -> 21712.2 | O35: Product01 | P35: =SUMIFS(InputData[SALES],InputData[PRODUCT],Functions!O35) -> 33761
B36: 33 | C36: =_xlfn.XLOOKUP(B36,InputData[WEEK],InputData[SALES]) -> 1787.94 | E36: Russia | F36: =SUMIFS(Country[Sales],Country[Country],Functions!E36) -> 3774 | L36: Customer12 | M36: =SUMIFS(InputData[SALES],InputData[CUSTOMER NAME],Functions!L36) -> 34247.45 | O36: Product30 | P36: =SUMIFS(InputData[SALES],InputData[PRODUCT],Functions!O36) -> 57968.64
B37: 34 | C37: =_xlfn.XLOOKUP(B37,InputData[WEEK],InputData[SALES]) -> 110.04 | E37: Mexico | F37: =SUMIFS(Country[Sales],Country[Country],Functions!E37) -> 1483.64 | L37: Customer02 | M37: =SUMIFS(InputData[SALES],InputData[CUSTOMER NAME],Functions!L37) -> 31336.23 | O37: Product17 | P37: =SUMIFS(InputData[SALES],InputData[PRODUCT],Functions!O37) -> 25555.14
B38: 35 | C38: =_xlfn.XLOOKUP(B38,InputData[WEEK],InputData[SALES]) -> 2956.59 | E38: Brazil | F38: =SUMIFS(Country[Sales],Country[Country],Functions!E38) -> 1492.48 | L38: Customer23 | M38: =SUMIFS(InputData[SALES],InputData[CUSTOMER NAME],Functions!L38) -> 43062.83 | O38: Product06 | P38: =SUMIFS(InputData[SALES],InputData[PRODUCT],Functions!O38) -> 16843.5
B39: 36 | C39: =_xlfn.XLOOKUP(B39,InputData[WEEK],InputData[SALES]) -> 699.6 | E39: South Africa | F39: =SUMIFS(Country[Sales],Country[Country],Functions!E39) -> 816.2 | L39: Customer28 | M39: =SUMIFS(InputData[SALES],InputData[CUSTOMER NAME],Functions!L39) -> 14337.4 | O39: Product05 | P39: =SUMIFS(InputData[SALES],InputData[PRODUCT],Functions!O39) -> 38591.28
B40: 37 | C40: =_xlfn.XLOOKUP(B40,InputData[WEEK],InputData[SALES]) -> 117.48 | E40: Ethiopia | F40: =SUMIFS(Country[Sales],Country[Country],Functions!E40) -> 1027.04 | L40: Customer10 | M40: =SUMIFS(InputData[SALES],InputData[CUSTOMER NAME],Functions!L40) -> 14222.83 | O40: Product27 | P40: =SUMIFS(InputData[SALES],InputData[PRODUCT],Functions!O40) -> 13880.16
B41: 38 | C41: =_xlfn.XLOOKUP(B41,InputData[WEEK],InputData[SALES]) -> 1217.16 | E41: France | F41: =SUMIFS(Country[Sales],Country[Country],Functions!E41) -> 62.88 | L41: Customer07 | M41: =SUMIFS(InputData[SALES],InputData[CUSTOMER NAME],Functions!L41) -> 8394.32 | O41: Product28 | P41: =SUMIFS(InputData[SALES],InputData[PRODUCT],Functions!O41) -> 6731.41
... B43: 40 | C43: =_xlfn.XLOOKUP(B43,InputData[WEEK],InputData[SALES]) -> 58.3 | E43: Germany | F43: =SUMIFS(Country[Sales],Country[Country],Functions!E43) -> 393 | L43: Customer40 | M43: =SUMIFS(InputData[SALES],InputData[CUSTOMER NAME],Functions!L43) -> 7572.25 | O43: Product39 | P43: =SUMIFS(InputData[SALES],InputData[PRODUCT],Functions!O43) -> 11786.35
...

Sheet Analysis
C3: Week | D3: Total Sales | F3: Month | G3: Sum of Total Sales | H3: Target | J3: Total Sales
C4: 1 | D4: 5179.59 | F4: Jan | G4: 92118.79 | H4: 90000 | J4: 984571.06
C5: 2 | D5: 21116.73 | F5: Feb | G5: 91137.05 | H5: 100000
C6: 3 | D6: 14261.19 | F6: Mar | G6: 97920.72 | H6: 100000
C7: 4 | D7: 11433.2 | F7: Apr | G7: 72320.89 | H7: 100000 | J7: Customer | K7: Total Sales
C8: 5 | D8: 33727.55 | F8: May | G8: 70511.76 | H8: 90000 | J8: Customer33 | K8: 60929.15
C9: 6 | D9: 34794.82 | F9: Jun | G9: 66727.4 | H9: 90000 | J9: Customer22 | K9: 45112.95
C10: 7 | D10: 32107.1 | F10: Jul | G10: 92661.55 | H10: 90000 | J10: Customer23 | K10: 43062.83
C11: 8 | D11: 11777.67 | F11: Aug | G11: 69125.75 | H11: 90000 | J11: Grand Total | K11: 149104.93
C12: 9 | D12: 17571.59 | F12: Sep | G12: 78253.53 | H12: 90000
C13: 10 | D13: 17413.3 | F13: Oct | G13: 87136.37 | H13: 80000
C14: 11 | D14: 18811.39 | F14: Nov | G14: 75659.86 | H14: 80000 | J14: Product | K14: Total Sales
C15: 12 | D15: 29446.46 | F15: Dec | G15: 90997.39 | H15: 80000 | J15: Product30 | K15: 57968.64
C16: 13 | D16: 22723.6 | F16: Grand Total | G16: 984571.06 | H16: 1080000 | J16: Product41 | K16: 57554.28
C17: 14 | D17: 13729.81 | J17: Product24 | K17: 49599.36
C18: 15 | D18: 27820.09 | J18: Product19 | K18: 41580
C19: 16 | D19: 9407.51 | F19: Region | G19: Sum of Sales | J19: Product22 | K19: 41055.3
C20: 17 | D20: 22127.3 | F20: Central | G20: 3283.91 | J20: Product32 | K20: 40883.04
C21: 18 | D21: 11809.4 | F21: East | G21: 2280.87 | J21: Product21 | K21: 39659.76
C22: 19 | D22: 12750.54 | F22: Export | G22: 23052.08 | J22: Product05 | K22: 38591.28
C23: 20 | D23: 19691.76 | F23: North | G23: 3415.8 | J23: Product42 | K23: 38232
C24: 21 | D24: 19171.71 | F24: Northeast | G24: 4045.14 | J24: Product10 | K24: 34991.64
C25: 22 | D25: 11617.86 | F25: South | G25: 812.01 | J25: Grand Total | K25: 440115.3
C26: 23 | D26: 17000.62 | F26: Western | G26: 3414.6
C27: 24 | D27: 15273.35 | F27: Grand Total | G27: 40304.41
C28: 25 | D28: 23043.47
C29: 26 | D29: 13593.79
C30: 27 | D30: 13197.89 | F30: Coountry | G30: Sum of Sales
C31: 28 | D31: 13311.34 | F31: Bangladesh | G31: 1436.4 | I31: {=OFFSET($F$30,1,0,COUNT($G$31:$G$45),2)} -> Bangladesh | J31: 1436.4
C32: 29 | D32: 26662.81 | F32: Brazil | G32: 1492.48 | I32: Brazil | J32: 1492.48
C33: 30 | D33: 15652.32 | F33: Ethiopia | G33: 1027.04 | I33: Ethiopia | J33: 1027.04
C34: 31 | D34: 27172.4 | F34: France | G34: 62.88 | I34: France | J34: 62.88
C35: 32 | D35: 6991.1 | F35: Germany | G35: 393 | I35: Germany | J35: 393
C36: 33 | D36: 17406.18 | F36: India | G36: 17252.33 | I36: India | J36: 17252.33
C37: 34 | D37: 10403.35 | F37: Indonesia | G37: 2464.2 | I37: Indonesia | J37: 2464.2
C38: 35 | D38: 29524.29 | F38: Mexico | G38: 1483.64 | I38: Mexico | J38: 1483.64
C39: 36 | D39: 14336.82 | F39: Nigeria | G39: 1240.98 | I39: Nigeria | J39: 1240.98
C40: 37 | D40: 15584.3 | F40: Pakistan | G40: 2520.19 | I40: Pakistan | J40: 2520.19
C41: 38 | D41: 13437.32 | F41: Russia | G41: 3774 | I41: Russia | J41: 3774
C42: 39 | D42: 30057.11 | F42: Saudi Arabia | G42: 1488 | I42: Saudi Arabia | J42: 1488
...

Sheet Dashboard
